所有异常类型都是内置类Throwable的子类，因而Throwable在异常类的层次结构的顶层。

Throwable分成了两个不同的分支，一个分支是Error，它表示不希望被程序捕获或者是程序无法处理的错误。另一个分支是Exception，它表示用户程序可能捕捉的异常情况或者说是程序可以处理的异常。其中异常类Exception又分为运行时异常(RuntimeException)和非运行时异常。

JAVA异常又可以分为不受检查的异常(Unchecked Exception)和检查异常(Checked Exception)

**Error：**Error类对象由JAVA虚拟机产生并抛出，大多数错误与代码编写者所执行的操作无关。如JAVA虚拟机运行错误（Virtual MachineError），当JVM不再有继续操作所需要的内存资源时会出现`outOfMemoryError`。这些异常发生时，JVM一般会选择线程终止。还有发生在虚拟机试图执行应用时，如类定义错误（NoClassDefFoundError)、连接错误（LinkageError）。这些错误是不可查的，因为他们在应用程序的控制和处理能力之外，而且绝大多数是程序运行时不允许出现的状况。在JAVA中，错误通常是使用JAVA的子类描述。

**Exception：**在`Exception`分支中有一个重要的子类`RuntimeException`(运行时异常)，该类型的异常自动为你所编写的程序定义`ArrayIndexOutOfBoundException`(数组小标越界)、`NullPointerEception`(空指针异常)、`ArithmeticException`(算数异常)、`MissingResourceException`(丢失资源)、`ClassNotFoundException`(找不到类)等异常。这些异常是不检查异常，程序中可以选择捕获处理，也可以选择不处理。这些异常一般是由程序逻辑错误引起的，程序应该从逻辑角度尽可能避免这类一场的发生。而`RuntimeException`之外的异常我们统称为非运行时异常，类型属于Exception及其子类，从程序语法角度讲是必须进行处理的异常。如果不处理那么编译就不能通过。如IOException、SQLException`等及用户自定义的Exception异常，一般情况下不定义检查异常。

**注：`Error`和`Exception`的区别：`Error`通常是灾难性的致命错误，是程序无法控制和处理的，当出现这些异常时，JVM一般会选择终止线程，`Exception`通常情况下是可以被程序处理的，并且在程序中应该尽可能的去处理这些异常。**

**检查异常：**在正确的程序运行过程中，是很容易出现的、情理可容得异常状况，在一定程度上这种异常得发生是可以预测得，并一旦发生这种异常就必须采取某种方式进行处理。除了`RuntimeException`及其子类以外，其他得`Exception`类及其子类都属于检查异常，当程序中可能出现这类异常时，要么使用try-catch语句进行捕获，要么使用throws抛出，否则编译无法通过。

不受检查异常：包括`RuntimeException`及其子类和`Error`。不受检查异常为编译器不要求强制处理得异常，检查异常是编译器要求得必须要处理得异常。

## Java异常处理机制

**Java异常处理得本质是抛出异常和捕获异常**

**抛出异常：**要理解抛出异常，首先要明白什么是异常情形(exception condition)，它是指当前方法或作用域继续执行的问题。其次把异常类型和普通问题相区分，普通问题是指在当前环境下能得到足够的信息，总能处理这个错误。对于异常情形，已经无法再继续下去了，因为在当前环境下无法获得必要的信息来解决问题你所能做的就是从当前环境跳出，并把问题交给上一级环境，这就是抛出异常时所发生的事情。抛出异常后，会有几件事随之发生。首先，是像创建普通的java对象一样将使用new在堆上创建一个异常对象；然后，当前的执行路径（已经无法继续下去了）被终止，并且从当前环境中弹出对异常对象的引用。此时，异常处理机制接管程序，并开始寻找一个恰当的地方继续执行程序，这个恰当的地方就是异常处理程序或异常处理器，他的任务是将程序从错误状态中恢复，以程使程序要么换一种方式运行，要么继续运行下去。

举个简单的例子，假如我们创建了一个学生对象`Student`的一个引用`stu`，在调用的时候可能还没有初始化。所以在使用这个对象引用调出其他方法之前要对他进行检查。可以创建一个代表错误信息的对象并将它从当前环境抛出，这样就把错误信息传播到更大的环境中。

```java
if(stu == null){
    throws new NullPointException();
}
```

抛出的异常能够在其他的地方得到处理。

**捕获异常：**在方法抛出异常后，运行时系统将转为寻找合适的异常处理器(exception handler)。潜在的异常处理器是异常发生时依次存留在调用栈中的方法的集合。当异常处理器所能处理的异常类型与方法抛出的异常类型相符时，即为合适的异常处理器。运行时系统从发生异常的方法开始，依次回查调用栈中的方法，直到找到有合适的异常处理方法并执行。当运行时系统便利调用栈而未找到合适的异常处理器时那么运行时系统会终止。同时意味着Java程序的终止。

对于`运行时异常`、`错误`和`检查异常`，Java技术所要求的异常处理方式有所不同。

由于运行时异常及其子类的不可查性，为了更合理、更容易地实现应用程序，Java规定，**运行时异常将由Java运行时系统自动抛出，允许应用程序忽略运行时异常**。

对于方法运行中可能出现的`Error`，当运行方法不欲捕捉时，Java允许该方法不做任何抛出声明。因为，大多数`Error`异常属于永远不能被允许发生的状况，也属于合理的应用程序不该捕捉的异常。

对于所有的检查异常，Java规定：一个方法必须捕捉，或者声明抛出方法之外。也就是说，当一个方法选择不捕捉检查异常时，它必须声明将抛出异常。

**Java异常处理涉及到五个关键字，分别是：`try`、`catch`、`finally`、`throw`、`throws`。**

`try`：用于监听。将要被监听的代码(可能抛出异常的代码)放在try语句块内，当try语句块内发生异常时一场就会被抛出。

`catch`：用于捕获异常。catch用来捕获try语句块中发生的异常

`finally`：finally语句块总是会被执行。它主要是用于回收try块里打开的物理资源（如数据库连接、网络连接和磁盘文件）。只有finally块执行完成后才会回来执行try或者catch块中的return或throw语句。如果finally中使用了return或throw等终止访问的语句，则不会跳回执行，直接停止。

`throw`：用于抛出异常

`throws`：用于在方法签名中，用于声名该方法可能抛出的异常

## try-catch

```java
try{
    //code that might generate exceptions    
}catch(Exception e){
    //the code of handling exception1
}catch(Exception e){
    //the code of handling exception2
}
```

要明白异常捕获，还要理解监控区域（guarded region)的概念。它是一段可能产生异常的代码，并且后面跟着处理这些异常的代码。

因而可知，上述`try-catch`所描述的即是监控区域，关键词`try`后的一对大括号将一块可能发生异常的代码包起来，即为监控区域。Java方法在运行过程中发生了异常，则创建异常对象。将异常抛出监控区域之外，由于Java运行时系统负责寻找匹配的`catch`子句来捕获异常。若有一个catch语句匹配到了则执行该`catch`块中的异常处理代码，就不再尝试匹配catch块了。匹配的原则：如果抛出的异常对象属于`catch`子句的异常类，或者属于该异常类的子类，则认为生成的异常对象与`catch`块捕获的异常类型相匹配。

例：

```java
public class TestException {  
    public static void main(String[] args) {  
        int a = 1;  
        int b = 0;  
        try { // try监控区域               
            if (b == 0) throw new ArithmeticException(); // 通过throw语句抛出异常  
            System.out.println("a/b的值是：" + a / b);  
            System.out.println("this will not be printed!");
        }  
        catch (ArithmeticException e) { // catch捕捉异常  
            System.out.println("程序出现异常，变量b不能为0！");  
        }  
        System.out.println("程序正常结束。");  
    }  
}
//输出
程序出现异常，变量b不能为0！

程序正常结束。
```

使用多重的catch语句：很多情况下，由单个代码段可能引起多个异常。处理这种情况，我们需要定义两个或更多的catch子句。每个子句捕获一种类型的异常，当异常被引发时，每个`catch`子句被依次检查，第一个匹配异常类型的子句执行，当一个`catch`子句执行以后，其他的子句将被旁路。

**捕获异常的顺序：**先小后大。Java通过异常类描述异常类型。对于有多个catch子句的异常程序而言，应该尽量将捕获底层异常类的catch子句放在前面，同时尽量将捕获相对高层的异常类的catch子句放在后面。否则，捕获底层异常类的catch子句将可能会被屏蔽（父类将所有底层异常都涵盖了）。 `RuntimeException`异常类包括运行时各种常见的异常，`ArithmeticException`类和`ArrayIndexOutOfBoundsException`类都是他的子类。因此，`RuntimeException`异常类的`catch`子句应该放在最后面，否则可能会屏蔽其后的特定异常处理或引起编译错误。

**嵌套try语句：**try语句可以被嵌套。也就是说一个try语句可以在另一个try块的内部。每次进入try语句，异常的前后关系都会被推入堆栈。如果一个内部的try语句不含特殊异常的`catch`程序，堆栈将被弹出，下一个try语句的catch处理程序将检查是否与之匹配。这个过程将继续直到一个catch语句被匹配成功，或者是直到所有的嵌套try语句被检查完毕。如果没有catch语句匹配，Java运行时系统将处理这个异常。如下：

```java
class NestTry{
    public static void main(String[] args){
        try{
            int a = args.length;
            int b = 42 / a;
            System.out.println("a = "+ a);
            try{
                if(a == 1){
                a = a/(a-a);
                }
                if(a == 2){
                    int c[] = {1};
                    c[42] =99;
                }
            }catch(ArrayIndexOutOfBoundsException e){
                System.out.println("ArrayIndexOutOfBounds :"+e);
            }    
        }catch(ArithmeticException e){
            System.out.println("Divide by 0"+ e);
        }
    }
}
```

正如程序中所显示的，该程序在一个try块中嵌套了另一个`try`块。程序工作如下：当你在没有命令行参数的情况下执行该程序，外面的`try`块将产生一个被0除的异常。程序在有一个命令行参数条件下执行，由嵌套的`try`块产生一个被0除的异常，由于内部的`catch`块不匹配这个异常，它将把异常传给外部的`try`块，在外部异常被处理。如果你在具有两个命令行参数的条件下执行该程序，将由内部`try`块产生一个数组边界异常。

结果：

```

Divide by 0 java.lang.ArithmeticExceptio: / by zero

D:\java>java NestTry one

a = 1

Divide by 0java.lang.ArithmeticException: / by zero

D:\java>java NestTry one two

a = 2

ArrayIndexOutOfBounds :java.lang.ArrayIndexOutOfBoundsException: 42
```

注意：当有方法调用时，`try`语句的嵌套可以很隐蔽的发生。例如，我们可以将对方法的调用放在一个`try`块中。在该方法的内部，有另一个`try`语句。在这种情况下，方法内部的`try`仍然是嵌套在外部调用该方法的`try`块中的。下面我们将对上述例子进行修改，嵌套的`try`块移到方法nesttry()的内部：

```java
class NestTry{
    static void nesttry(int a){
        try{
            if(a == 1){
                a = a/(a-a);
            }
            if(a == 2){
                int c[] = {1};
                c[42] =99;
            }
        }catch(ArrayIndexOutOfBoundsException e){
            System.out.println("ArrayIndexOutOfBounds :"+e);
        }    
    }
    public static void main(String[] args){
        try{
            int a = args.length;
            int b = 42 / a;
            System.out.println("a = "+ a);
            nesttry(a);
        }catch(ArithmeticException e){
            System.out.println("Divide by 0"+ e);
        }
    }
}
```

结果输出与前面例子一致：

```java
D:\java>javac NestTry.java

D:\java>java NestTry

Divide by 0java.lang.ArithmeticException: / by zero

D:\java>java NestTry one

a = 1

Divide by 0java.lang.ArithmeticException: / by zero

D:\java>java NestTry one two

a = 2

ArrayIndexOutOfBounds :java.lang.ArrayIndexOutOfBoundsException: 42
```

我们所调用的方法内部还有一个try块，这个try块可以看作是嵌在主方法的try下的。

## throw

到目前为止，我们只是获取了被Java运行时系统引发的异常。然而我们还可以用throw语句抛出明确的异常。throw的语法形式如：`throw ThrowableInstance`。

这里的`ThrowableInstance`一定是`Thrwoable`类型或者`Throwable`子类型的一个对象。象是简单的数据类型，如：`int, char`或非`Thrwoable`类，如`String, Object`都不能作为异常。有两种方法可以获取`Thrwoable`对象：在`catch`子句中使用参数或通过`new`创建。

程序执行完`throw`语句之后立即停止；throw后的任何语句不被执行，最邻近的try块用来检查它是否含有一个与异常类型相匹配的`catch`语句。如果发现了匹配的块，控制转向该语句，如果没有发现，向外寻找try块来检查，依次类推。如果没有发现匹配的catch块，默认异常处理程序中断程序的执行并打印堆栈轨迹。

```java
class TestThrow{
    static void proc(){
        try{
            throw new NullPointerException("demo"); //throw后程序停止，随后检查这个try块中是否有一个与异常类型相匹配的catch语句。
        }catch(NullPointerException e){ //发现匹配块，捕获throwable对象
            System.out.println("Caught inside proc"); //捕获异常
            throw e; //将NullPointerException类型的实例e抛出
        }
    }

    public static void main(String [] args){
        try{
            proc(); //抛出一个NullPointException异常
        }catch(NullPointerException e){ //捕获异常
            System.out.println("Recaught: "+e); //含有字符串参数的异常对象当作print的参数时会将字符串输出
        }
    }
}
//输出
Caught inside proc

Recaught: java.lang.NullPointerException: demo
```

该程序两次处理相同的错误，首先，main()方法设立了一个异常关系然后调用proc()。proc()方法设立了另一个异常关系并抛出一个`NullPointException`实例，`NullPointException`在main()中再一次被捕获。

注：`throw new NullPointException("demo")`此处用`new`来构造一个`NullPointException`实例，所有的Java内置的运行时异常有两个构造方法：一个没有参数，一个带有一个字符串参数。当用第二种形式时，参数指定描述异常的字符串。如果对象用作`print()`或`println()`的参数时，该字符串被显示。这同样可以通过`getMessage()`来实现，`getMessage()`是由`Thrwoable`定义的。

## throws

如果一个方法可以导致一个异常但不处理它，它必须指定这种行为以使方法的调用者可以保护他们自己而不发生异常。要做到这点，我们可以在方法声名中包含一个`throws`子句。一个`throws`子句列举了一个方法可能引发的所有异常类型。这对于除了`Error`或`RuntimeException`以及他们子类以外类型的所有异常是必要的。一个方法可以引发的所有其他类型的异常必须在`throws`子句中声名，否则会导致编译错误。

**下面是`throws`子句的方法声名的通形式：**

```java
public void info() throws Exception{
    //body of method
}
```

**如：**

```java
class TestThrows{
    static void throw1(){
        System.out.println("Inside throw1 . ");
        throw new IllegalAccessException("demo");
    }
    public static void main(String[] args){
        throw1();
    }
}
```

上述程序有两处错误：首先，`throw1()`方法不想处理所导致的异常，因而它必须声明`throws`子句来列举可能引发的异常(IllegalAccessException)。其次在main()方法中并没有定义try/catch块来捕获异常，

**正确的做法：**

```java
class TestThrows{
    static void throw1() throws IllegalAccessException {
        System.out.println("Inside throw1 . ");
        throw new IllegalAccessException("demo");
    }
    public static void main(String[] args){
        try {
            throw1();
        }catch(IllegalAccessException e ){
            System.out.println("Caught " + e);
        }
    }
}
```

**`Throws`抛出异常的规则：**

- 如果是不受检查异常（`unchecked exception`），即`Error`、`RuntimeException`或它们的子类，那么可以不使用`throws`关键字来声明要抛出的异常，编译仍能顺利通过，但在运行时会被系统抛出。
- 必须声明方法可抛出的任何检查异常（`checked exception`）。即如果一个方法可能出现受可查异常，要么用`try-catch`语句捕获，要么用`throws`子句声明将它抛出，否则会导致编译错误
- 仅当抛出了异常，该方法的调用者才必须处理或者重新抛出该异常。当方法的调用者无力处理该异常的时候，应该继续抛出，而不是囫囵吞枣。
- 调用方法必须遵循任何可查异常的处理和声明规则。若覆盖一个方法，则不能声明与覆盖方法不同的异常。声明的任何异常必须是被覆盖方法所声明异常的同类或子类。

## finally

当异常发生时，通常方法的执行将做一个陡峭的非线性的转向，它甚至会过早的导致方法返回。例如，如果一个方法打开了一个文件并关闭，然后退出，你不希望关闭文件的代码被异常处理机制旁路。`finally`关键字为处理这种意外而设计。

`finally`创建的代码块在`try/catch`块完成之后另一个`try/catch`出现之前执行。`finally`块无论有没有异常抛出都会执行。如果抛出异常，即使没有`catch`子句匹配，`finally`也会执行。一个方法将从一个`try/catch`块返回到调用程序的任何时候，经过一个未捕获的异常或者是一个明确的返回语句，`finally`子句在方法返回之前仍将执行。这在关闭文件句柄和释放任何在方法开始时被分配的其他资源是很有用。

> `finally`子句是可选项，可以有也可以无，但是每个`try`语句至少需要一个`catch`或者`finally`子句。

```java
class TestFinally{
    static void proc1(){
        try{
            System.out.println("inside proc1");
            throw new RuntimeException("demo");
        }finally{
            System.out.println("proc1's finally");
        }
    }
    static void proc2(){
        try{
            System.out.println("inside proc2");
            return ;
        } finally{
            System.out.println("proc2's finally");
        }
    } 
    static void proc3(){
        try{
            System.out.println("inside proc3");
        }finally{
            System.out.println("proc3's finally");
        }
    }
    public static void main(String [] args){
        try{
            proc1();
        }catch(Exception e){
            System.out.println("Exception caught");
        }
        proc2();
        proc3();
    }
}
```

该例子中，proc1()抛出了异常中断了`try`，它的`finally`子句在退出时执行。proc2的`try`语句通过`return`语句返回，但在返回之前`finally`语句执行。在proc3()中`try`语句正常执行，没有错误，`finally`语句也被执行。

输出结果：

```
D:\java>java TestFinally

inside proc1

proc1's finally

Exception caught

inside proc2
 
proc2's finally
 
inside proc3
 
proc3's finally
```

> 注：如果`finally`块与一个`try`联合使用，`finally`块将在`try`结束之前执行。

### **问题扩展（面试题）**：

**1、try{} 里有一个 return 语句，那么紧跟在这个 try 后的 finally{} 里的 code 会不会被执行，什么时候被执行，在 return 前还是后?**

答案：会执行，在方法返回调用者前执行。

> **注意：**在finally中改变返回值的做法是不好的，因为如果存在finally代码块，try中的return语句不会立马返回调用者，而是记录下返回值待finally代码块执行完毕之后再向调用者返回其值，然后如果在finally中修改了返回值，就会返回修改后的值。显然，在finally中返回或者修改返回值会对程序造成很大的困扰，C#中直接用编译错误的方式来阻止程序员干这种龌龊的事情，Java中也可以通过提升编译器的语法检查级别来产生警告或错误，Eclipse中可以在如图所示的地方进行设置，强烈建议将此项设置为编译错误。

**2、Java语言如何进行异常处理，关键字：throws、throw、try、catch、finally分别如何使用？**

答：Java通过面向对象的方法进行异常处理，把各种不同的异常进行分类，并提供了良好的接口。在Java中，每个异常都是一个对象，它是Throwable类或其子类的实例。当一个方法出现异常后便抛出一个异常对象，该对象中包含有异常信息，调用这个对象的方法可以捕获到这个异常并可以对其进行处理。Java的异常处理是通过5个关键词来实现的：try、catch、throw、throws和finally。一般情况下是用try来执行一段程序，如果系统会抛出（throw）一个异常对象，可以通过它的类型来捕获（catch）它，或通过总是执行代码块（finally）来处理；try用来指定一块预防所有异常的程序；catch子句紧跟在try块后面，用来指定你想要捕获的异常的类型；throw语句用来明确地抛出一个异常；throws用来声明一个方法可能抛出的各种异常（当然声明异常时允许无病呻吟）；finally为确保一段代码不管发生什么异常状况都要被执行；try语句可以嵌套，每当遇到一个try语句，异常的结构就会被放入异常栈中，直到所有的try语句都完成。如果下一级的try语句没有对某种异常进行处理，异常栈就会执行出栈操作，直到遇到有处理这种异常的try语句或者最终将异常抛给JVM。

**3、运行时异常与受检异常有何异同？** 

答：异常表示程序运行过程中可能出现的非正常状态，运行时异常表示虚拟机的通常操作中可能遇到的异常，是一种常见运行错误，只要程序设计得没有问题通常就不会发生。受检异常跟程序运行的上下文环境有关，即使程序设计无误，仍然可能因使用的问题而引发。Java编译器要求方法必须声明抛出可能发生的受检异常，但是并不要求必须声明抛出未被捕获的运行时异常。异常和继承一样，是面向对象程序设计中经常被滥用的东西，在*Effective Java*中对异常的使用给出了以下指导原则： 
\- 不要将异常处理用于正常的控制流（设计良好的API不应该强迫它的调用者为了正常的控制流而使用异常） 
\- 对可以恢复的情况使用受检异常，对编程错误使用运行时异常 
\- 避免不必要的使用受检异常（可以通过一些状态检测手段来避免异常的发生） 
\- 优先使用标准的异常 
\- 每个方法抛出的异常都要有文档 
\- 保持异常的原子性 
\- 不要在catch中忽略掉捕获到的异常

**4、列出一些你常见的运行时异常？** 

答： 
\- ArithmeticException（算术异常） 
\- ClassCastException （类转换异常） 
\- IllegalArgumentException （非法参数异常） 
\- IndexOutOfBoundsException （下标越界异常） 
\- NullPointerException （空指针异常） 
\- SecurityException （安全异常）

 <img src="https://images2015.cnblogs.com/blog/690102/201607/690102-20160729131101138-1250422700.jpg" alt="img" style="zoom:150%;" />

## 异常链

异常链顾名思义就是将异常发生的原因一个传一个串起来，即把底层的异常信息传给上层，这样逐层抛出。 Java API文档中给出了一个简单的模型：

```
try {   
    lowLevelOp();   
} catch (LowLevelException le) {   
    throw (HighLevelException) new HighLevelException().initCause(le);   
}
```

当程序捕获到了一个底层异常，在处理部分选择了继续抛出一个更高级别的新异常给此方法的调用者。 这样异常的原因就会逐层传递。这样，位于高层的异常递归调用getCause()方法，就可以遍历各层的异常原因。 这就是`Java异常链`的原理。异常链的实际应用很少，发生异常时候逐层上抛不是个好注意， 上层拿到这些异常又能奈之何？而且异常逐层上抛会消耗大量资源， 因为要保存一个完整的异常链信息.

## 自定义异常

使用Java内置的异常类可以描述在编程时出现的大部分异常情况。除此之外，用户还可以自定义异常。用户自定义异常类，只需继承`Exception`类即可。

在程序中使用自定义异常类，大体可分为以下几个步骤:

- 创建自定义异常类。
- 在方法中通过`throw`关键字抛出异常对象。
- 如果在当前抛出异常的方法中处理异常，可以使用`try-catch`语句捕获并处理；否则在方法的声明处通过`throws`关键字指明要抛出给方法调用者的异常，继续进行下一步操作。
- 在出现异常方法的调用者中捕获并处理异常。

举例自定义异常：

```java
class MyException extends Exception {
    private int detail;
    MyException(int a){
        detail = a;
    }
    public String toString(){
        return "MyException ["+ detail + "]";
    }
}
public class TestMyException{
    static void compute(int a) throws MyException{
        System.out.println("Called compute(" + a + ")");
        if(a > 10){
            throw new MyException(a);
        }
        System.out.println("Normal exit!");
    }
    public static void main(String [] args){
        try{
            compute(1);
            compute(20);
        }catch(MyException me){
            System.out.println("Caught " + me);
        }
    }
}
```

该例子完全按照上述步骤。

```
运行结果如下：
D:\java>java TestMyException

Called compute(1)

Normal exit!

Called compute(20)

Caught MyException [20]
```

## 总结

 ![img](https://images2015.cnblogs.com/blog/690102/201607/690102-20160729105042231-937633681.jpg)

![img](https://images2015.cnblogs.com/blog/690102/201607/690102-20160729100445981-600538221.jpg)